Workbook

Sheet Sheet1
A1: variable_name | B1: file_name | C1: IS_CATEGORICAL | D1: IS_KEEP | E1: reason_to_drop
A2: SEQN | C2: FALSE | D2: TRUE | E2: also, it doesn't have to be perfect for multicollinearity. We're going to do VIF test later. | F2: =COUNTIF(D:D,TRUE) -> 264
A3: LBXGH | C3: FALSE | D3: TRUE | E3: same for leakage, we will do some leakage test.
A4: SDDSRVYR_Data_release_cycle | B4: P_DEMO | C4: TRUE | D4: TRUE | E4: just make sure we don't have too many collinearity and leakage.
A5: RIDSTATR_Interview_Examination_status | B5: P_DEMO | C5: TRUE | D5: TRUE
A6: RIAGENDR_Gender | B6: P_DEMO | C6: TRUE | D6: TRUE
A7: RIDAGEYR_Age_in_years_at_screening | B7: P_DEMO | C7: FALSE | D7: TRUE
A8: RIDRETH1_Race_Hispanic_origin | B8: P_DEMO | C8: TRUE | D8: FALSE | E8: collinear with RIDRETH3. RIDRETH3 is more informative since include an additional race value
A9: RIDRETH3_Race_Hispanic_origin_w_NH_Asian | B9: P_DEMO | C9: TRUE | D9: TRUE
A10: RIDEXMON_Six_month_time_period | B10: P_DEMO | C10: TRUE | D10: TRUE
A11: DMDBORN4_Country_of_birth | B11: P_DEMO | C11: TRUE | D11: TRUE
A12: DMDEDUC2_Education_level_Adults_20 | B12: P_DEMO | C12: TRUE | D12: TRUE
A13: DMDMARTZ_Marital_status | B13: P_DEMO | C13: TRUE | D13: TRUE
A14: SIALANG_Language_of_SP_Interview | B14: P_DEMO | C14: TRUE | D14: FALSE | E14: survey design/survey process variables, not predictor for health patterns
A15: SIAPROXY_Proxy_used_in_SP_Interview | B15: P_DEMO | C15: TRUE | D15: FALSE | E15: survey design/survey process variables, not predictor for health patterns
A16: SIAINTRP_Interpreter_used_in_SP_Interview | B16: P_DEMO | C16: TRUE | D16: FALSE | E16: survey design/survey process variables, not predictor for health patterns
A17: FIALANG_Language_of_Family_Interview | B17: P_DEMO | C17: TRUE | D17: FALSE | E17: survey design/survey process variables, not predictor for health patterns
A18: FIAPROXY_Proxy_used_in_Family_Interview | B18: P_DEMO | C18: TRUE | D18: FALSE | E18: survey design/survey process variables, not predictor for health patterns
A19: FIAINTRP_Interpreter_used_in_Family_Interview | B19: P_DEMO | C19: TRUE | D19: FALSE | E19: survey design/survey process variables, not predictor for health patterns
A20: MIALANG_Language_of_MEC_Interview | B20: P_DEMO | C20: TRUE | D20: FALSE | E20: survey design/survey process variables, not predictor for health patterns
A21: MIAPROXY_Proxy_used_in_MEC_Interview | B21: P_DEMO | C21: TRUE | D21: FALSE | E21: survey design/survey process variables, not predictor for health patterns
A22: MIAINTRP_Interpreter_used_in_MEC_Interview | B22: P_DEMO | C22: TRUE | D22: FALSE | E22: survey design/survey process variables, not predictor for health patterns
A23: AIALANGA_Language_of_ACASI_Interview | B23: P_DEMO | C23: TRUE | D23: FALSE | E23: survey design/survey process variables, not predictor for health patterns
A24: WTINTPRP_Full_sample_interview_weight | B24: P_DEMO | C24: FALSE | D24: FALSE | E24: survey design/survey process variables, not predictor for health patterns
A25: WTMECPRP_Full_sample_MEC_exam_weight | B25: P_DEMO | C25: FALSE | D25: FALSE | E25: survey design/survey process variables, not predictor for health patterns
... A27: SDMVSTRA_Masked_variance_pseudo_stratum | B27: P_DEMO | C27: TRUE | D27: FALSE | E27: survey design/survey process variables, not predictor for health patterns
A28: INDFMPIR_Ratio_of_family_income_to_poverty | B28: P_DEMO | C28: FALSE | D28: TRUE
A29: BMDSTATS_Body_Measures_Component_Status_Code | B29: P_BMX | C29: TRUE | D29: TRUE
A30: BMXWT_Weight_kg | B30: P_BMX | C30: FALSE | D30: TRUE
A31: BMXHT_Standing_Height_cm | B31: P_BMX | C31: FALSE | D31: TRUE
A32: BMXBMI_Body_Mass_Index_kg_m_2 | B32: P_BMX | C32: FALSE | D32: TRUE
A33: BMXLEG_Upper_Leg_Length_cm | B33: P_BMX | C33: FALSE | D33: TRUE
A34: BMXARML_Upper_Arm_Length_cm | B34: P_BMX | C34: FALSE | D34: TRUE
A35: BMXARMC_Arm_Circumference_cm | B35: P_BMX | C35: FALSE | D35: TRUE
A36: BMXWAIST_Waist_Circumference_cm | B36: P_BMX | C36: FALSE | D36: TRUE
A37: BMXHIP_Hip_Circumference_cm | B37: P_BMX | C37: FALSE | D37: TRUE
A38: BPAOARM_Arm_selected_oscillometric | B38: P_BPXO | C38: TRUE | D38: TRUE
A39: BPAOCSZ_Coded_cuff_size_oscillometric | B39: P_BPXO | C39: TRUE | D39: TRUE
A40: BPXOSY1_Systolic_1st_oscillometric_reading | B40: P_BPXO | C40: FALSE | D40: TRUE | E40: This needs to be merged since collinear. Merged to median.
A41: BPXODI1_Diastolic_1st_oscillometric_reading | B41: P_BPXO | C41: FALSE | D41: TRUE | E41: This needs to be merged since collinear. Merged to median.
...

Sheet check
A1: variable_name | B1: python
A2: SEQN | B2: SEQN
A3: LBXGH | B3: LBXGH
A4: SDDSRVYR_Data_release_cycle | B4: P_DEMO__SDDSRVYR_Data_release_cycle
A5: RIDSTATR_Interview_Examination_status | B5: P_DEMO__RIDSTATR_Interview_Examination_status
A6: RIAGENDR_Gender | B6: P_DEMO__RIAGENDR_Gender
A7: RIDAGEYR_Age_in_years_at_screening | B7: P_DEMO__RIDAGEYR_Age_in_years_at_screening
A8: RIDRETH3_Race_Hispanic_origin_w_NH_Asian | B8: P_DEMO__RIDRETH3_Race_Hispanic_origin_w_NH_Asian
A9: RIDEXMON_Six_month_time_period | B9: P_DEMO__RIDEXMON_Six_month_time_period
A10: DMDBORN4_Country_of_birth | B10: P_DEMO__DMDBORN4_Country_of_birth
A11: DMDEDUC2_Education_level_Adults_20 | B11: P_DEMO__DMDEDUC2_Education_level_Adults_20
A12: DMDMARTZ_Marital_status | B12: P_DEMO__DMDMARTZ_Marital_status
... A267: Thiazolidinedione (TZD) | B267: Thiazolidinedione (TZD)

Sheet check 2
A1: P_DEMO__RIDAGEYR_Age_in_years_at_screening
A2: P_DEMO__INDFMPIR_Ratio_of_family_income_to_poverty
A3: P_BMX__BMXWT_Weight_kg
A4: P_BMX__BMXHT_Standing_Height_cm
A5: P_BMX__BMXBMI_Body_Mass_Index_kg_m_2
A6: P_BMX__BMXLEG_Upper_Leg_Length_cm
A7: P_BMX__BMXARML_Upper_Arm_Length_cm
A8: P_BMX__BMXARMC_Arm_Circumference_cm
A9: P_BMX__BMXWAIST_Waist_Circumference_cm
A10: P_BMX__BMXHIP_Hip_Circumference_cm
A11: P_LUX__LUXSMED_Median_stiffness_E_kilopascals_kPa
A12: P_LUX__LUXCAPM_Median_CAP_decibels_per_meter_dB_m
... A143: P_DEMO__DMDMARTZ_Marital_status_3.0
A144: P_DEMO__DMDMARTZ_Marital_status_77.0 | B144: check
A145: P_DEMO__DMDMARTZ_Marital_status_99.0 | B145: check
A146: P_BMX__BMDSTATS_Body_Measures_Component_Status_Code_2.0
A147: P_BMX__BMDSTATS_Body_Measures_Component_Status_Code_3.0
A148: P_BMX__BMDSTATS_Body_Measures_Component_Status_Code_4.0
A149: P_BPXO__BPAOARM_Arm_selected_oscillometric_R
A150: P_BPXO__BPAOCSZ_Coded_cuff_size_oscillometric_3.0
A151: P_BPXO__BPAOCSZ_Coded_cuff_size_oscillometric_4.0
A152: P_BPXO__BPAOCSZ_Coded_cuff_size_oscillometric_5.0
A153: P_OHXDEN__OHDEXSTS_Overall_Oral_Health_Exam_Status_2.0
A154: P_OHXDEN__OHDEXSTS_Overall_Oral_Health_Exam_Status_3.0
A155: P_OHXDEN__OHDDESTS_Dentition_Status_Code_2.0
A156: P_OHXDEN__OHDDESTS_Dentition_Status_Code_3.0
A157: P_OHXDEN__OHXIMP_Dental_Implant_yes_no_2.0
... A215: P_DBQ__DBQ229_Regular_milk_use_5_times_per_week_3.0
A216: P_DBQ__DBD895_of_meals_not_home_prepared_1.0 | B216: bin?
A217: P_DBQ__DBD895_of_meals_not_home_prepared_2.0 | B217: bin?
A218: P_DBQ__DBD895_of_meals_not_home_prepared_3.0 | B218: bin?
A219: P_DBQ__DBD895_of_meals_not_home_prepared_4.0 | B219: bin?
A220: P_DBQ__DBD895_of_meals_not_home_prepared_5.0 | B220: bin?
A221: P_DBQ__DBD895_of_meals_not_home_prepared_6.0 | B221: bin?
A222: P_DBQ__DBD895_of_meals_not_home_prepared_7.0 | B222: bin?
A223: P_DBQ__DBD895_of_meals_not_home_prepared_8.0 | B223: bin?
A224: P_DBQ__DBD895_of_meals_not_home_prepared_9.0 | B224: bin?
A225: P_DBQ__DBD895_of_meals_not_home_prepared_10.0 | B225: bin?
A226: P_DBQ__DBD895_of_meals_not_home_prepared_11.0 | B226: bin?
A227: P_DBQ__DBD895_of_meals_not_home_prepared_12.0 | B227: bin?
...

Sheet init_selection
A1: variable_name | B1: IS_CATEGORICAL | C1: IS_KEEP
A2: =Sheet1!A2 -> SEQN | B2: =Sheet1!C2 -> FALSE | C2: =Sheet1!D2 -> TRUE
A3: =Sheet1!A3 -> LBXGH | B3: =Sheet1!C3 -> FALSE | C3: =Sheet1!D3 -> TRUE
A4: =Sheet1!A4 -> SDDSRVYR_Data_release_cycle | B4: =Sheet1!C4 -> TRUE | C4: =Sheet1!D4 -> TRUE
A5: =Sheet1!A5 -> RIDSTATR_Interview_Examination_status | B5: =Sheet1!C5 -> TRUE | C5: =Sheet1!D5 -> TRUE
A6: =Sheet1!A6 -> RIAGENDR_Gender | B6: =Sheet1!C6 -> TRUE | C6: =Sheet1!D6 -> TRUE
A7: =Sheet1!A7 -> RIDAGEYR_Age_in_years_at_screening | B7: =Sheet1!C7 -> FALSE | C7: =Sheet1!D7 -> TRUE
A8: =Sheet1!A8 -> RIDRETH1_Race_Hispanic_origin | B8: =Sheet1!C8 -> TRUE | C8: =Sheet1!D8 -> FALSE
A9: =Sheet1!A9 -> RIDRETH3_Race_Hispanic_origin_w_NH_Asian | B9: =Sheet1!C9 -> TRUE | C9: =Sheet1!D9 -> TRUE
A10: =Sheet1!A10 -> RIDEXMON_Six_month_time_period | B10: =Sheet1!C10 -> TRUE | C10: =Sheet1!D10 -> TRUE
A11: =Sheet1!A11 -> DMDBORN4_Country_of_birth | B11: =Sheet1!C11 -> TRUE | C11: =Sheet1!D11 -> TRUE
A12: =Sheet1!A12 -> DMDEDUC2_Education_level_Adults_20 | B12: =Sheet1!C12 -> TRUE | C12: =Sheet1!D12 -> TRUE
A13: =Sheet1!A13 -> DMDMARTZ_Marital_status | B13: =Sheet1!C13 -> TRUE | C13: =Sheet1!D13 -> TRUE
... A521: =Sheet1!A521 -> WHQ150_Age_when_heaviest_weight | B521: =Sheet1!C521 -> FALSE | C521: =Sheet1!D521 -> TRUE

Sheet survey prefix
A1: P_ALQ
A2: P_AUQ
A3: P_BPQ
A4: P_CBQPFC
A5: P_DBQ
A6: P_DIQ
A7: P_DPQ
A8: P_FSQ
A9: P_HEQ
A10: P_HIQ
A11: P_HSQ
A12: P_HUQ
... A16: P_MCQ
